Workbook
Name UPDATE: 'Data Sheet'!$E$1

Sheet FINANCIALS>

Sheet HISTORIACLFINANCIALS
B2: ="HISTORICAL FINANCIAL STATEMENT - "&'Data Sheet'!B1 -> HISTORICAL FINANCIAL STATEMENT - MARUTI SUZUKI INDIA LTD
B3: YEARS | C3: ='Data Sheet'!B16 -> 42460 | D3: ='Data Sheet'!C16 -> 42825 | E3: ='Data Sheet'!D16 -> 43190 | F3: ='Data Sheet'!E16 -> 43555 | G3: ='Data Sheet'!F16 -> 43921 | H3: ='Data Sheet'!G16 -> 44286 | I3: ='Data Sheet'!H16 -> 44651 | J3: ='Data Sheet'!I16 -> 45016 | ... L3: ='Data Sheet'!K16 -> 45747 | M3: LTM
A4: # | B4: INCOME STATEMENT (in cr.)
B5: SALES | C5: =IFERROR('Data Sheet'!B17,0) -> 57589 | D5: =IFERROR('Data Sheet'!C17,0) -> 68085 | E5: =IFERROR('Data Sheet'!D17,0) -> 79809.4 | F5: =IFERROR('Data Sheet'!E17,0) -> 86068.5 | G5: =IFERROR('Data Sheet'!F17,0) -> 75660 | H5: =IFERROR('Data Sheet'!G17,0) -> 70372 | I5: =IFERROR('Data Sheet'!H17,0) -> 88329.8 | J5: =IFERROR('Data Sheet'!I17,0) -> 117571.3 | ... L5: =IFERROR('Data Sheet'!K17,0) -> 152913 | M5: =IFERROR(SUM('Data Sheet'!H42:K42),0) -> 171773.6
B6: SALES GROWTH | C6: - | D6: =D5/C5-1 -> 0.18225703 | E6: =E5/D5-1 -> 0.17220239 | F6: =F5/E5-1 -> 0.078425599 | G6: =G5/F5-1 -> -0.12093275 | H6: =H5/G5-1 -> -0.06989162 | I6: =I5/H5-1 -> 0.25518388 | J6: =J5/I5-1 -> 0.33104909 | K6: =K5/J5-1 -> 0.20657167 | ... M6: =M5/L5-1 -> 0.12334203
B8: COGS | C8: =IFERROR(SUM('Data Sheet'!B18,'Data Sheet'!B20:B22)-1*'Data Sheet'!B19,0) -> 41828.2 | D8: =IFERROR(SUM('Data Sheet'!C18,'Data Sheet'!C20:C22)-1*'Data Sheet'!C19,0) -> 50004 | E8: =IFERROR(SUM('Data Sheet'!D18,'Data Sheet'!D20:D22)-1*'Data Sheet'!D19,0) -> 58985 | F8: =IFERROR(SUM('Data Sheet'!E18,'Data Sheet'!E20:E22)-1*'Data Sheet'!E19,0) -> 64182.2 | G8: =IFERROR(SUM('Data Sheet'!F18,'Data Sheet'!F20:F22)-1*'Data Sheet'!F19,0) -> 57657.1 | H8: =IFERROR(SUM('Data Sheet'!G18,'Data Sheet'!G20:G22)-1*'Data Sheet'!G19,0) -> 55415.6 | I8: =IFERROR(SUM('Data Sheet'!H18,'Data Sheet'!H20:H22)-1*'Data Sheet'!H19,0) -> 71578.8 | J8: =IFERROR(SUM('Data Sheet'!I18,'Data Sheet'!I20:I22)-1*'Data Sheet'!I19,0) -> 92796.1 | ... L8: =IFERROR(SUM('Data Sheet'!K18,'Data Sheet'!K20:K22)-1*'Data Sheet'!K19,0) -> 117563.8 | M8: =IFERROR(SUM('Data Sheet'!H43:K43),0) -> 151647.9
B9: COGS%SALES | C9: =C8/C5 -> 0.72632274 | D9: =D8/D5 -> 0.7344349 | E9: =E8/E5 -> 0.73907334 | F9: =F8/F5 -> 0.74571068 | G9: =G8/G5 -> 0.76205525 | H9: =H8/H5 -> 0.78746661 | I9: =I8/I5 -> 0.81035845 | J9: =J8/J5 -> 0.7892751 | ... M9: =M8/M5 -> 0.8828359
B11: GROSS PROFIT | C11: =IFERROR(C5-C8,0) -> 15760.8 | D11: =IFERROR(D5-D8,0) -> 18081 | E11: =IFERROR(E5-E8,0) -> 20824.4 | F11: =IFERROR(F5-F8,0) -> 21886.3 | G11: =IFERROR(G5-G8,0) -> 18002.9 | H11: =IFERROR(H5-H8,0) -> 14956.4 | I11: =IFERROR(I5-I8,0) -> 16751 | J11: =IFERROR(J5-J8,0) -> 24775.2 | ... M11: =IFERROR(M5-M8,0) -> 20125.7
B12: GROSS MARGIN | C12: =IFERROR(C11/C5,0) -> 0.27367726 | D12: =IFERROR(D11/D5,0) -> 0.2655651 | E12: =IFERROR(E11/E5,0) -> 0.26092666 | F12: =IFERROR(F11/F5,0) -> 0.25428932 | G12: =IFERROR(G11/G5,0) -> 0.23794475 | H12: =IFERROR(H11/H5,0) -> 0.21253339 | I12: =IFERROR(I11/I5,0) -> 0.18964155 | J12: =IFERROR(J11/J5,0) -> 0.2107249 | ... M12: =IFERROR(M11/M5,0) -> 0.1171641
B14: S&G EXPENSES | C14: =IFERROR(SUM('Data Sheet'!C23:C24),0) -> 7659.7 | D14: =IFERROR(SUM('Data Sheet'!D23:D24),0) -> 8706.5 | E14: =IFERROR(SUM('Data Sheet'!E23:E24),0) -> 10830 | F14: =IFERROR(SUM('Data Sheet'!F23:F24),0) -> 10647.9 | G14: =IFERROR(SUM('Data Sheet'!G23:G24),0) -> 9545.8 | H14: =IFERROR(SUM('Data Sheet'!H23:H24),0) -> 10999 | I14: =IFERROR(SUM('Data Sheet'!I23:I24),0) -> 13746 | J14: =IFERROR(SUM('Data Sheet'!J23:J24),0) -> 15216.7 | ... L14: =IFERROR(SUM('Data Sheet'!L23:L24),0) -> 0
B15: S&G EXPENSES%SALES | C15: =IFERROR(C14/C5,0) -> 0.1330063 | D15: =IFERROR(D14/D5,0) -> 0.12787692 | E15: =IFERROR(E14/E5,0) -> 0.1356983 | F15: =IFERROR(F14/F5,0) -> 0.12371425 | G15: =IFERROR(G14/G5,0) -> 0.12616706 | H15: =IFERROR(H14/H5,0) -> 0.15629796 | I15: =IFERROR(I14/I5,0) -> 0.15562132 | J15: =IFERROR(J14/J5,0) -> 0.12942529 | ... M15: =IFERROR(M14/M5,0) -> 0
B17: EBITDA | C17: =IFERROR(C5-C8-C14,0) -> 8101.1 | D17: =IFERROR(D5-D8-D14,0) -> 9374.5 | E17: =IFERROR(E5-E8-E14,0) -> 9994.4 | F17: =IFERROR(F5-F8-F14,0) -> 11238.4 | G17: =IFERROR(G5-G8-G14,0) -> 8457.1 | H17: =IFERROR(H5-H8-H14,0) -> 3957.4 | I17: =IFERROR(I5-I8-I14,0) -> 3005 | J17: =IFERROR(J5-J8-J14,0) -> 9558.5 | ... M17: =IFERROR(M5-M8-M14,0) -> 20125.7
B18: EBITDA%SALES | C18: =IFERROR(C17/C5,0) -> 0.14067096 | D18: =IFERROR(D17/D5,0) -> 0.13768818 | E18: =IFERROR(E17/E5,0) -> 0.12522836 | F18: =IFERROR(F17/F5,0) -> 0.13057507 | G18: =IFERROR(G17/G5,0) -> 0.11177769 | H18: =IFERROR(H17/H5,0) -> 0.056235435 | I18: =IFERROR(I17/I5,0) -> 0.034020229 | J18: =IFERROR(J17/J5,0) -> 0.081299603 | ... M18: =IFERROR(M17/M5,0) -> 0.1171641
B20: INTEREST | C20: =IFERROR('Data Sheet'!B27,0) -> 81.7 | D20: =IFERROR('Data Sheet'!C27,0) -> 89.4 | E20: =IFERROR('Data Sheet'!D27,0) -> 345.8 | F20: =IFERROR('Data Sheet'!E27,0) -> 75.9 | G20: =IFERROR('Data Sheet'!F27,0) -> 134.2 | H20: =IFERROR('Data Sheet'!G27,0) -> 101.8 | I20: =IFERROR('Data Sheet'!H27,0) -> 126.6 | J20: =IFERROR('Data Sheet'!I27,0) -> 187 | ... L20: =IFERROR('Data Sheet'!K27,0) -> 194.2 | M20: =IFERROR(SUM('Data Sheet'!H46:K46),0) -> 213.3
B21: INTEREST%SALES | C21: =IFERROR(C20/C5,0) -> 0.0014186737 | D21: =IFERROR(D20/D5,0) -> 0.0013130646 | E21: =IFERROR(E20/E5,0) -> 0.004332823 | F21: =IFERROR(F20/F5,0) -> 0.00088185573 | G21: =IFERROR(G20/G5,0) -> 0.0017737246 | H21: =IFERROR(H20/H5,0) -> 0.0014465981 | I21: =IFERROR(I20/I5,0) -> 0.0014332649 | J21: =IFERROR(J20/J5,0) -> 0.0015905242 | ... M21: =IFERROR(M20/M5,0) -> 0.0012417508
B23: DEPRECIATION | C23: =IFERROR('Data Sheet'!C26,0) -> 2603.9 | D23: =IFERROR('Data Sheet'!D26,0) -> 2759.8 | E23: =IFERROR('Data Sheet'!E26,0) -> 3020.8 | F23: =IFERROR('Data Sheet'!F26,0) -> 3528.4 | G23: =IFERROR('Data Sheet'!G26,0) -> 3034.1 | H23: =IFERROR('Data Sheet'!H26,0) -> 2789 | I23: =IFERROR('Data Sheet'!I26,0) -> 2825.7 | J23: =IFERROR('Data Sheet'!J26,0) -> 5255.8 | ... L23: =IFERROR('Data Sheet'!L26,0) -> 0 | M23: =IFERROR(SUM('Data Sheet'!H45:K45),0) -> 6455.4
B24: DEPRECIATION%SALES | C24: =IFERROR(C23/C5,0) -> 0.045215232 | D24: =IFERROR(D23/D5,0) -> 0.040534626 | E24: =IFERROR(E23/E5,0) -> 0.037850178 | F24: =IFERROR(F23/F5,0) -> 0.040995254 | G24: =IFERROR(G23/G5,0) -> 0.040101771 | H24: =IFERROR(H23/H5,0) -> 0.03963224 | I24: =IFERROR(I23/I5,0) -> 0.031990336 | J24: =IFERROR(J23/J5,0) -> 0.044703087 | ... M24: =IFERROR(M23/M5,0) -> 0.037580862
B26: EARNING BEFORE TAX | C26: =IFERROR(C17-C23,0) -> 5497.2 | D26: =IFERROR(D17-D23,0) -> 6614.7 | E26: =IFERROR(E17-E23,0) -> 6973.6 | F26: =IFERROR(F17-F23,0) -> 7710 | G26: =IFERROR(G17-G23,0) -> 5423 | H26: =IFERROR(H17-H23,0) -> 1168.4 | I26: =IFERROR(I17-I23,0) -> 179.3 | J26: =IFERROR(J17-J23,0) -> 4302.7 | ... M26: =IFERROR(M17-M23,0) -> 13670.3
B27: EBT%SALES | C27: =IFERROR(C26/C5,0) -> 0.095455729 | D27: =IFERROR(D26/D5,0) -> 0.097153558 | E27: =IFERROR(E26/E5,0) -> 0.087378179 | F27: =IFERROR(F26/F5,0) -> 0.089579811 | G27: =IFERROR(G26/G5,0) -> 0.071675919 | H27: =IFERROR(H26/H5,0) -> 0.016603194 | I27: =IFERROR(I26/I5,0) -> 0.0020298925 | J27: =IFERROR(J26/J5,0) -> 0.036596516 | ... M27: =IFERROR(M26/M5,0) -> 0.079583242
B29: TAX | C29: =IFERROR('Data Sheet'!B29,0) -> 2087.5 | D29: =IFERROR('Data Sheet'!C29,0) -> 2616.2 | E29: =IFERROR('Data Sheet'!D29,0) -> 3286.2 | F29: =IFERROR('Data Sheet'!E29,0) -> 2973.2 | G29: =IFERROR('Data Sheet'!F29,0) -> 1425.2 | H29: =IFERROR('Data Sheet'!G29,0) -> 931.9 | I29: =IFERROR('Data Sheet'!H29,0) -> 817.7 | J29: =IFERROR('Data Sheet'!I29,0) -> 2112.1 | ... L29: =IFERROR('Data Sheet'!K29,0) -> 5119.8 | M29: =IFERROR(SUM('Data Sheet'!H48:K48),0) -> 4186.2
B30: EFFECTIVE TAX RATE | C30: =IFERROR(C29/C26,0) -> 0.37973878 | D30: =IFERROR(D29/D26,0) -> 0.39551302 | E30: =IFERROR(E29/E26,0) -> 0.47123437 | F30: =IFERROR(F29/F26,0) -> 0.38562905 | G30: =IFERROR(G29/G26,0) -> 0.26280656 | H30: =IFERROR(H29/H26,0) -> 0.79758644 | I30: =IFERROR(I29/I26,0) -> 4.5605131 | J30: =IFERROR(J29/J26,0) -> 0.49087782 | ... M30: =IFERROR(M29/M26,0) -> 0.30622591
B32: NET PROFIT | C32: =IFERROR(C26-C29,0) -> 3409.7 | D32: =IFERROR(D26-D29,0) -> 3998.5 | E32: =IFERROR(E26-E29,0) -> 3687.4 | F32: =IFERROR(F26-F29,0) -> 4736.8 | G32: =IFERROR(G26-G29,0) -> 3997.8 | H32: =IFERROR(H26-H29,0) -> 236.5 | I32: =IFERROR(I26-I29,0) -> -638.4 | J32: =IFERROR(J26-J29,0) -> 2190.6 | ... L32: =IFERROR(L26-L29,0) -> 30229.4 | M32: =IFERROR(SUM('Data Sheet'!H49:K49),0) -> 14931.6
B33: NET MARGINS | C33: =IFERROR(C32/C5,0) -> 0.059207488 | D33: =IFERROR(D32/D5,0) -> 0.058728061 | E33: =IFERROR(E32/E5,0) -> 0.046202578 | F33: =IFERROR(F32/F5,0) -> 0.055035234 | G33: =IFERROR(G32/G5,0) -> 0.052839017 | H33: =IFERROR(H32/H5,0) -> 0.0033607116 | I33: =IFERROR(I32/I5,0) -> -0.0072274589 | J33: =IFERROR(J32/J5,0) -> 0.018632098 | ... M33: =IFERROR(M32/M5,0) -> 0.086926047
B35: NO OF EQUITY SHARE | C35: =IFERROR('Data Sheet'!B93,0) -> 30.21 | D35: =IFERROR('Data Sheet'!C93,0) -> 30.21 | E35: =IFERROR('Data Sheet'!D93,0) -> 30.21 | F35: =IFERROR('Data Sheet'!E93,0) -> 30.21 | G35: =IFERROR('Data Sheet'!F93,0) -> 30.21 | H35: =IFERROR('Data Sheet'!G93,0) -> 30.21 | I35: =IFERROR('Data Sheet'!H93,0) -> 30.21 | J35: =IFERROR('Data Sheet'!I93,0) -> 30.21 | ... L35: =IFERROR('Data Sheet'!K93,0) -> 31.44 | M35: 31.44
B37: EPS | C37: =IFERROR(C32/C35,0) -> 112.8666 | D37: =IFERROR(D32/D35,0) -> 132.35684 | E37: =IFERROR(E32/E35,0) -> 122.05892 | F37: =IFERROR(F32/F35,0) -> 156.79576 | G37: =IFERROR(G32/G35,0) -> 132.33366 | H37: =IFERROR(H32/H35,0) -> 7.8285336 | I37: =IFERROR(I32/I35,0) -> -21.132075 | J37: =IFERROR(J32/J35,0) -> 72.512413 | ... M37: =IFERROR(M32/M35,0) -> 474.92366
B38: EPS GROWTH% | C38: - | D38: =IFERROR(D37/C37-1,0) -> 0.17268381 | E38: =IFERROR(E37/D37-1,0) -> -0.077804177 | F38: =IFERROR(F37/E37-1,0) -> 0.28459077 | G38: =IFERROR(G37/F37-1,0) -> -0.1560125 | H38: =IFERROR(H37/G37-1,0) -> -0.94084246 | I38: =IFERROR(I37/H37-1,0) -> -3.6993658 | J38: =IFERROR(J37/I37-1,0) -> -4.431391 | K38: =IFERROR(K37/J37-1,0) -> 3.0235719 | ... M38: =IFERROR(M37/L37-1,0) -> -0.50605702
B40: DIVIDEND PER SHARE | C40: =IFERROR('Data Sheet'!B31/HISTORIACLFINANCIALS!C35,0) -> 34.988414 | D40: =IFERROR('Data Sheet'!C31/HISTORIACLFINANCIALS!D35,0) -> 74.975174 | E40: =IFERROR('Data Sheet'!D31/HISTORIACLFINANCIALS!E35,0) -> 79.973519 | F40: =IFERROR('Data Sheet'!E31/HISTORIACLFINANCIALS!F35,0) -> 79.973519 | G40: =IFERROR('Data Sheet'!F31/HISTORIACLFINANCIALS!G35,0) -> 59.980139 | H40: =IFERROR('Data Sheet'!G31/HISTORIACLFINANCIALS!H35,0) -> 44.985104 | I40: =IFERROR('Data Sheet'!H31/HISTORIACLFINANCIALS!I35,0) -> 59.980139 | J40: =IFERROR('Data Sheet'!I31/HISTORIACLFINANCIALS!J35,0) -> 89.970209 | ... M40: =IFERROR('Data Sheet'!L31/HISTORIACLFINANCIALS!M35,0) -> 0
B41: DIVIDEND PAY OUT RATIO | C41: =IFERROR(C40/C37,0) -> 0.30999795 | D41: =IFERROR(D40/D37,0) -> 0.56646242 | E41: =IFERROR(E40/E37,0) -> 0.65520421 | F41: =IFERROR(F40/F37,0) -> 0.51004898 | G41: =IFERROR(G40/G37,0) -> 0.45324929 | H41: =IFERROR(H40/H37,0) -> 5.7463002 | I41: =IFERROR(I40/I37,0) -> -2.8383459 | J41: =IFERROR(J40/J37,0) -> 1.240756 | ... M41: =IFERROR(M40/M37,0) -> 0
B43: RETAINED EARNING | D43: =IFERROR(1-D41,0) -> 0.43353758 | E43: =IFERROR(1-E41,0) -> 0.34479579 | F43: =IFERROR(1-F41,0) -> 0.48995102 | G43: =IFERROR(1-G41,0) -> 0.54675071 | H43: =IFERROR(1-H41,0) -> -4.7463002 | I43: =IFERROR(1-I41,0) -> 3.8383459 | J43: =IFERROR(1-J41,0) -> -0.24075596 | K43: =IFERROR(1-K41,0) -> 0.57156406 | ... M43: =IFERROR(1-M41,0) -> 1
A45: # | B45: BALANCE SHEET (in cr.)
B46: =IFERROR('Data Sheet'!A57,0) -> Equity Share Capital | C46: =IFERROR('Data Sheet'!B57,0) -> 151 | D46: =IFERROR('Data Sheet'!C57,0) -> 151 | E46: =IFERROR('Data Sheet'!D57,0) -> 151 | F46: =IFERROR('Data Sheet'!E57,0) -> 151 | G46: =IFERROR('Data Sheet'!F57,0) -> 151 | H46: =IFERROR('Data Sheet'!G57,0) -> 151 | I46: =IFERROR('Data Sheet'!H57,0) -> 151 | ... L46: =IFERROR('Data Sheet'!K57,0) -> 157.2
B47: =IFERROR('Data Sheet'!A58,0) -> Reserves | C47: =IFERROR('Data Sheet'!B58,0) -> 30465 | D47: =IFERROR('Data Sheet'!C58,0) -> 36924.1 | E47: =IFERROR('Data Sheet'!D58,0) -> 42408.4 | F47: =IFERROR('Data Sheet'!E58,0) -> 46941.1 | G47: =IFERROR('Data Sheet'!F58,0) -> 49262 | H47: =IFERROR('Data Sheet'!G58,0) -> 52349.6 | I47: =IFERROR('Data Sheet'!H58,0) -> 55182.5 | ... L47: =IFERROR('Data Sheet'!K58,0) -> 96082.7
B48: =IFERROR('Data Sheet'!A59,0) -> Borrowings | C48: =IFERROR('Data Sheet'!B59,0) -> 230.9 | D48: =IFERROR('Data Sheet'!C59,0) -> 483.6 | E48: =IFERROR('Data Sheet'!D59,0) -> 120.8 | F48: =IFERROR('Data Sheet'!E59,0) -> 159.6 | G48: =IFERROR('Data Sheet'!F59,0) -> 184.1 | H48: =IFERROR('Data Sheet'!G59,0) -> 540.9 | I48: =IFERROR('Data Sheet'!H59,0) -> 425.5 | ... L48: =IFERROR('Data Sheet'!K59,0) -> 87
B49: =IFERROR('Data Sheet'!A60,0) -> Other Liabilities | C49: =IFERROR('Data Sheet'!B60,0) -> 11878.6 | D49: =IFERROR('Data Sheet'!C60,0) -> 14401.8 | E49: =IFERROR('Data Sheet'!D60,0) -> 17568.2 | F49: =IFERROR('Data Sheet'!E60,0) -> 16717 | G49: =IFERROR('Data Sheet'!F60,0) -> 14030.6 | H49: =IFERROR('Data Sheet'!G60,0) -> 18334.6 | I49: =IFERROR('Data Sheet'!H60,0) -> 18896.5 | ... L49: =IFERROR('Data Sheet'!K60,0) -> 35644.3
B50: TOTAL LIABILITIES | C50: =IFERROR(SUM(C46:C49),0) -> 42725.5 | D50: =IFERROR(SUM(D46:D49),0) -> 51960.5 | E50: =IFERROR(SUM(E46:E49),0) -> 60248.4 | F50: =IFERROR(SUM(F46:F49),0) -> 63968.7 | G50: =IFERROR(SUM(G46:G49),0) -> 63627.7 | H50: =IFERROR(SUM(H46:H49),0) -> 71376.1 | I50: =IFERROR(SUM(I46:I49),0) -> 74655.5 | J50: =IFERROR(SUM(J46:J49),0) -> 84596.9 | ... L50: =IFERROR(SUM(L46:L49),0) -> 131971.2
B52: Fixed Asset Net Block | C52: =IFERROR('Data Sheet'!B62,0) -> 12529.6 | D52: =IFERROR('Data Sheet'!C62,0) -> 13310.7 | E52: =IFERROR('Data Sheet'!D62,0) -> 13388.8 | F52: =IFERROR('Data Sheet'!E62,0) -> 15437.3 | G52: =IFERROR('Data Sheet'!F62,0) -> 15744.4 | H52: =IFERROR('Data Sheet'!G62,0) -> 14988.7 | I52: =IFERROR('Data Sheet'!H62,0) -> 13747.2 | J52: =IFERROR('Data Sheet'!I62,0) -> 17830.4 | ... L52: =IFERROR('Data Sheet'!K62,0) -> 32982.7
B53: =IFERROR('Data Sheet'!A63,0) -> Capital Work in Progress | C53: =IFERROR('Data Sheet'!B63,0) -> 1006.9 | D53: =IFERROR('Data Sheet'!C63,0) -> 1252.3 | E53: =IFERROR('Data Sheet'!D63,0) -> 2132.1 | F53: =IFERROR('Data Sheet'!E63,0) -> 1606.9 | G53: =IFERROR('Data Sheet'!F63,0) -> 1415.2 | H53: =IFERROR('Data Sheet'!G63,0) -> 1496.8 | I53: =IFERROR('Data Sheet'!H63,0) -> 2936.5 | ... L53: =IFERROR('Data Sheet'!K63,0) -> 7929
B54: =IFERROR('Data Sheet'!A64,0) -> Investments | C54: =IFERROR('Data Sheet'!B64,0) -> 20675.8 | D54: =IFERROR('Data Sheet'!C64,0) -> 29150.6 | E54: =IFERROR('Data Sheet'!D64,0) -> 36123.1 | F54: =IFERROR('Data Sheet'!E64,0) -> 37503.6 | G54: =IFERROR('Data Sheet'!F64,0) -> 37488 | H54: =IFERROR('Data Sheet'!G64,0) -> 42944.8 | I54: =IFERROR('Data Sheet'!H64,0) -> 42034.7 | ... L54: =IFERROR('Data Sheet'!K64,0) -> 66265.4
B55: =IFERROR('Data Sheet'!A65,0) -> Other Assets | C55: =IFERROR('Data Sheet'!B65-SUM('Data Sheet'!B67:B69),0) -> 4006.5 | D55: =IFERROR('Data Sheet'!C65-SUM('Data Sheet'!C67:C69),0) -> 3757.1 | E55: =IFERROR('Data Sheet'!D65-SUM('Data Sheet'!D67:D69),0) -> 3904.8 | F55: =IFERROR('Data Sheet'!E65-SUM('Data Sheet'!E67:E69),0) -> 3597.7 | G55: =IFERROR('Data Sheet'!F65-SUM('Data Sheet'!F67:F69),0) -> 3759.5 | H55: =IFERROR('Data Sheet'!G65-SUM('Data Sheet'!G67:G69),0) -> 4569.8 | I55: =IFERROR('Data Sheet'!H65-SUM('Data Sheet'!H67:H69),0) -> 7328.1 | J55: =IFERROR('Data Sheet'!I65-SUM('Data Sheet'!I67:I69),0) -> 7051.6 | ... L55: =IFERROR('Data Sheet'!K65-SUM('Data Sheet'!K67:K69),0) -> 10788.3
B56: Total Non-Current Assets | C56: =IFERROR(SUM(C52:C55),0) -> 38218.8 | D56: =IFERROR(SUM(D52:D55),0) -> 47470.7 | E56: =IFERROR(SUM(E52:E55),0) -> 55548.8 | F56: =IFERROR(SUM(F52:F55),0) -> 58145.5 | G56: =IFERROR(SUM(G52:G55),0) -> 58407.1 | H56: =IFERROR(SUM(H52:H55),0) -> 64000.1 | I56: =IFERROR(SUM(I52:I55),0) -> 66046.5 | J56: =IFERROR(SUM(J52:J55),0) -> 76970.4 | ... L56: =IFERROR(SUM(L52:L55),0) -> 117965.4
...

Sheet RATIO ANALYSIS
B2: ="RATIO ANALYSIS - "&'Data Sheet'!B1 -> RATIO ANALYSIS - MARUTI SUZUKI INDIA LTD
B3: YEARS | C3: ='Data Sheet'!B16 -> 42460 | D3: ='Data Sheet'!C16 -> 42825 | E3: ='Data Sheet'!D16 -> 43190 | F3: ='Data Sheet'!E16 -> 43555 | G3: ='Data Sheet'!F16 -> 43921 | H3: ='Data Sheet'!G16 -> 44286 | I3: ='Data Sheet'!H16 -> 44651 | J3: ='Data Sheet'!I16 -> 45016 | ... L3: ='Data Sheet'!K16 -> 45747 | M3: TREND | N3: MEAN | O3: MEDIAN
B5: Sales Growth | C5: - | D5: =IFERROR(HISTORIACLFINANCIALS!D6,0) -> 0.18225703 | E5: =IFERROR(HISTORIACLFINANCIALS!E6,0) -> 0.17220239 | F5: =IFERROR(HISTORIACLFINANCIALS!F6,0) -> 0.078425599 | G5: =IFERROR(HISTORIACLFINANCIALS!G6,0) -> -0.12093275 | H5: =IFERROR(HISTORIACLFINANCIALS!H6,0) -> -0.06989162 | I5: =IFERROR(HISTORIACLFINANCIALS!I6,0) -> 0.25518388 | J5: =IFERROR(HISTORIACLFINANCIALS!J6,0) -> 0.33104909 | K5: =IFERROR(HISTORIACLFINANCIALS!K6,0) -> 0.20657167 | L5: =IFERROR(HISTORIACLFINANCIALS!L6,0) -> 0.077928523 | N5: =IFERROR(AVERAGE(D5:L5),0) -> 0.12364376 | O5: =IFERROR(MEDIAN(D5:L5),0) -> 0.17220239
B6: EBITDA Growth | D6: =IFERROR(HISTORIACLFINANCIALS!D17/HISTORIACLFINANCIALS!C17-1,0) -> 0.15718853 | E6: =IFERROR(HISTORIACLFINANCIALS!E17/HISTORIACLFINANCIALS!D17-1,0) -> 0.066126193 | F6: =IFERROR(HISTORIACLFINANCIALS!F17/HISTORIACLFINANCIALS!E17-1,0) -> 0.1244697 | G6: =IFERROR(HISTORIACLFINANCIALS!G17/HISTORIACLFINANCIALS!F17-1,0) -> -0.24748185 | H6: =IFERROR(HISTORIACLFINANCIALS!H17/HISTORIACLFINANCIALS!G17-1,0) -> -0.53206182 | I6: =IFERROR(HISTORIACLFINANCIALS!I17/HISTORIACLFINANCIALS!H17-1,0) -> -0.24066306 | J6: =IFERROR(HISTORIACLFINANCIALS!J17/HISTORIACLFINANCIALS!I17-1,0) -> 2.1808652 | K6: =IFERROR(HISTORIACLFINANCIALS!K17/HISTORIACLFINANCIALS!J17-1,0) -> 0.95819428 | L6: =IFERROR(HISTORIACLFINANCIALS!L17/HISTORIACLFINANCIALS!K17-1,0) -> 0.88857427 | N6: =IFERROR(AVERAGE(D6:L6),0) -> 0.37280127 | O6: =IFERROR(MEDIAN(D6:L6),0) -> 0.1244697
B7: EBIT Growth | D7: =IFERROR(HISTORIACLFINANCIALS!D26/HISTORIACLFINANCIALS!C26-1,0) -> 0.20328531 | E7: =IFERROR(HISTORIACLFINANCIALS!E26/HISTORIACLFINANCIALS!D26-1,0) -> 0.054257941 | F7: =IFERROR(HISTORIACLFINANCIALS!F26/HISTORIACLFINANCIALS!E26-1,0) -> 0.10559826 | G7: =IFERROR(HISTORIACLFINANCIALS!G26/HISTORIACLFINANCIALS!F26-1,0) -> -0.29662776 | H7: =IFERROR(HISTORIACLFINANCIALS!H26/HISTORIACLFINANCIALS!G26-1,0) -> -0.7845473 | I7: =IFERROR(HISTORIACLFINANCIALS!I26/HISTORIACLFINANCIALS!H26-1,0) -> -0.84654228 | J7: =IFERROR(HISTORIACLFINANCIALS!J26/HISTORIACLFINANCIALS!I26-1,0) -> 22.997211 | K7: =IFERROR(HISTORIACLFINANCIALS!K26/HISTORIACLFINANCIALS!J26-1,0) -> 2.0467381 | L7: =IFERROR(HISTORIACLFINANCIALS!L26/HISTORIACLFINANCIALS!K26-1,0) -> 1.6965185 | N7: =IFERROR(AVERAGE(D7:L7),0) -> 2.7973213 | O7: =IFERROR(MEDIAN(D7:L7),0) -> 0.10559826
B8: Net Profit Growth | D8: =IFERROR(HISTORIACLFINANCIALS!D32/HISTORIACLFINANCIALS!C32-1,0) -> 0.17268381 | E8: =IFERROR(HISTORIACLFINANCIALS!E32/HISTORIACLFINANCIALS!D32-1,0) -> -0.077804177 | F8: =IFERROR(HISTORIACLFINANCIALS!F32/HISTORIACLFINANCIALS!E32-1,0) -> 0.28459077 | G8: =IFERROR(HISTORIACLFINANCIALS!G32/HISTORIACLFINANCIALS!F32-1,0) -> -0.1560125 | H8: =IFERROR(HISTORIACLFINANCIALS!H32/HISTORIACLFINANCIALS!G32-1,0) -> -0.94084246 | I8: =IFERROR(HISTORIACLFINANCIALS!I32/HISTORIACLFINANCIALS!H32-1,0) -> -3.6993658 | J8: =IFERROR(HISTORIACLFINANCIALS!J32/HISTORIACLFINANCIALS!I32-1,0) -> -4.431391 | K8: =IFERROR(HISTORIACLFINANCIALS!K32/HISTORIACLFINANCIALS!J32-1,0) -> 3.1873916 | L8: =IFERROR(HISTORIACLFINANCIALS!L32/HISTORIACLFINANCIALS!K32-1,0) -> 2.2955118 | N8: =IFERROR(AVERAGE(D8:L8),0) -> -0.37391532 | O8: =IFERROR(MEDIAN(D8:L8),0) -> -0.077804177
B9: Dividend Growth | D9: =IFERROR(HISTORIACLFINANCIALS!D40/HISTORIACLFINANCIALS!C40-1,0) -> 1.1428571 | E9: =IFERROR(HISTORIACLFINANCIALS!E40/HISTORIACLFINANCIALS!D40-1,0) -> 0.066666667 | F9: =IFERROR(HISTORIACLFINANCIALS!F40/HISTORIACLFINANCIALS!E40-1,0) -> 0 | G9: =IFERROR(HISTORIACLFINANCIALS!G40/HISTORIACLFINANCIALS!F40-1,0) -> -0.25 | H9: =IFERROR(HISTORIACLFINANCIALS!H40/HISTORIACLFINANCIALS!G40-1,0) -> -0.25 | I9: =IFERROR(HISTORIACLFINANCIALS!I40/HISTORIACLFINANCIALS!H40-1,0) -> 0.33333333 | J9: =IFERROR(HISTORIACLFINANCIALS!J40/HISTORIACLFINANCIALS!I40-1,0) -> 0.5 | K9: =IFERROR(HISTORIACLFINANCIALS!K40/HISTORIACLFINANCIALS!J40-1,0) -> 0.38934879 | L9: =IFERROR(HISTORIACLFINANCIALS!L40/HISTORIACLFINANCIALS!K40-1,0) -> 0.08 | N9: =IFERROR(AVERAGE(D9:L9),0) -> 0.22357844 | O9: =IFERROR(MEDIAN(D9:L9),0) -> 0.08
B11: Gross Margin | C11: =HISTORIACLFINANCIALS!C12 -> 0.27367726 | D11: =HISTORIACLFINANCIALS!D12 -> 0.2655651 | E11: =HISTORIACLFINANCIALS!E12 -> 0.26092666 | F11: =HISTORIACLFINANCIALS!F12 -> 0.25428932 | G11: =HISTORIACLFINANCIALS!G12 -> 0.23794475 | H11: =HISTORIACLFINANCIALS!H12 -> 0.21253339 | I11: =HISTORIACLFINANCIALS!I12 -> 0.18964155 | J11: =HISTORIACLFINANCIALS!J12 -> 0.2107249 | ... L11: =HISTORIACLFINANCIALS!L12 -> 0.23117197 | N11: =IFERROR(AVERAGE(C11:L11),0) -> 0.23750441 | O11: =IFERROR(MEDIAN(C11:L11),0) -> 0.23825699
B12: EBITDA Margin | C12: =HISTORIACLFINANCIALS!C18 -> 0.14067096 | D12: =HISTORIACLFINANCIALS!D18 -> 0.13768818 | E12: =HISTORIACLFINANCIALS!E18 -> 0.12522836 | F12: =HISTORIACLFINANCIALS!F18 -> 0.13057507 | G12: =HISTORIACLFINANCIALS!G18 -> 0.11177769 | H12: =HISTORIACLFINANCIALS!H18 -> 0.056235435 | I12: =HISTORIACLFINANCIALS!I18 -> 0.034020229 | J12: =HISTORIACLFINANCIALS!J18 -> 0.081299603 | ... L12: =HISTORIACLFINANCIALS!L18 -> 0.23117197 | N12: =IFERROR(AVERAGE(C12:L12),0) -> 0.11806119 | O12: =IFERROR(MEDIAN(C12:L12),0) -> 0.12790171
B13: EBIT Margin | C13: =IFERROR(HISTORIACLFINANCIALS!C17-HISTORIACLFINANCIALS!C23,0)/HISTORIACLFINANCIALS!C5-1 -> -0.90454427 | D13: =IFERROR(HISTORIACLFINANCIALS!D17-HISTORIACLFINANCIALS!D23,0)/HISTORIACLFINANCIALS!D5-1 -> -0.90284644 | E13: =IFERROR(HISTORIACLFINANCIALS!E17-HISTORIACLFINANCIALS!E23,0)/HISTORIACLFINANCIALS!E5-1 -> -0.91262182 | F13: =IFERROR(HISTORIACLFINANCIALS!F17-HISTORIACLFINANCIALS!F23,0)/HISTORIACLFINANCIALS!F5-1 -> -0.91042019 | G13: =IFERROR(HISTORIACLFINANCIALS!G17-HISTORIACLFINANCIALS!G23,0)/HISTORIACLFINANCIALS!G5-1 -> -0.92832408 | H13: =IFERROR(HISTORIACLFINANCIALS!H17-HISTORIACLFINANCIALS!H23,0)/HISTORIACLFINANCIALS!H5-1 -> -0.98339681 | I13: =IFERROR(HISTORIACLFINANCIALS!I17-HISTORIACLFINANCIALS!I23,0)/HISTORIACLFINANCIALS!I5-1 -> -0.99797011 | J13: =IFERROR(HISTORIACLFINANCIALS!J17-HISTORIACLFINANCIALS!J23,0)/HISTORIACLFINANCIALS!J5-1 -> -0.96340348 | ... L13: =IFERROR(HISTORIACLFINANCIALS!L17-HISTORIACLFINANCIALS!L23,0)/HISTORIACLFINANCIALS!L5-1 -> -0.76882803 | N13: =IFERROR(AVERAGE(C13:L13),0) -> -0.91799446 | O13: =IFERROR(MEDIAN(C13:L13),0) -> -0.91152101
B14: EBT Margin | C14: =HISTORIACLFINANCIALS!C27 -> 0.095455729 | D14: =HISTORIACLFINANCIALS!D27 -> 0.097153558 | E14: =HISTORIACLFINANCIALS!E27 -> 0.087378179 | F14: =HISTORIACLFINANCIALS!F27 -> 0.089579811 | G14: =HISTORIACLFINANCIALS!G27 -> 0.071675919 | H14: =HISTORIACLFINANCIALS!H27 -> 0.016603194 | I14: =HISTORIACLFINANCIALS!I27 -> 0.0020298925 | J14: =HISTORIACLFINANCIALS!J27 -> 0.036596516 | ... L14: =HISTORIACLFINANCIALS!L27 -> 0.23117197 | N14: =IFERROR(AVERAGE(C14:L14),0) -> 0.082005536 | O14: =IFERROR(MEDIAN(C14:L14),0) -> 0.088478995
B15: Net Profit Margin | C15: =HISTORIACLFINANCIALS!C33 -> 0.059207488 | D15: =HISTORIACLFINANCIALS!D33 -> 0.058728061 | E15: =HISTORIACLFINANCIALS!E33 -> 0.046202578 | F15: =HISTORIACLFINANCIALS!F33 -> 0.055035234 | G15: =HISTORIACLFINANCIALS!G33 -> 0.052839017 | H15: =HISTORIACLFINANCIALS!H33 -> 0.0033607116 | I15: =HISTORIACLFINANCIALS!I33 -> -0.0072274589 | J15: =HISTORIACLFINANCIALS!J33 -> 0.018632098 | ... L15: =HISTORIACLFINANCIALS!L33 -> 0.19769019 | N15: =IFERROR(AVERAGE(C15:L15),0) -> 0.054913038 | O15: =IFERROR(MEDIAN(C15:L15),0) -> 0.053937125
B17: SalesExpenses%Sales | C17: =HISTORIACLFINANCIALS!C15 -> 0.1330063 | D17: =HISTORIACLFINANCIALS!D15 -> 0.12787692 | E17: =HISTORIACLFINANCIALS!E15 -> 0.1356983 | F17: =HISTORIACLFINANCIALS!F15 -> 0.12371425 | G17: =HISTORIACLFINANCIALS!G15 -> 0.12616706 | H17: =HISTORIACLFINANCIALS!H15 -> 0.15629796 | I17: =HISTORIACLFINANCIALS!I15 -> 0.15562132 | J17: =HISTORIACLFINANCIALS!J15 -> 0.12942529 | ... L17: =HISTORIACLFINANCIALS!L15 -> 0 | N17: =IFERROR(AVERAGE(C17:L17),0) -> 0.11944322 | O17: =IFERROR(MEDIAN(C17:L17),0) -> 0.12865111
B18: Depreciation%Sales | C18: =HISTORIACLFINANCIALS!C24 -> 0.045215232 | D18: =HISTORIACLFINANCIALS!D24 -> 0.040534626 | E18: =HISTORIACLFINANCIALS!E24 -> 0.037850178 | F18: =HISTORIACLFINANCIALS!F24 -> 0.040995254 | G18: =HISTORIACLFINANCIALS!G24 -> 0.040101771 | H18: =HISTORIACLFINANCIALS!H24 -> 0.03963224 | I18: =HISTORIACLFINANCIALS!I24 -> 0.031990336 | J18: =HISTORIACLFINANCIALS!J24 -> 0.044703087 | ... L18: =HISTORIACLFINANCIALS!L24 -> 0 | N18: =IFERROR(AVERAGE(C18:L18),0) -> 0.036055657 | O18: =IFERROR(MEDIAN(C18:L18),0) -> 0.039867006
B19: Operating%Sales | C19: =C13 -> -0.90454427 | D19: =D13 -> -0.90284644 | E19: =E13 -> -0.91262182 | F19: =F13 -> -0.91042019 | G19: =G13 -> -0.92832408 | H19: =H13 -> -0.98339681 | I19: =I13 -> -0.99797011 | J19: =J13 -> -0.96340348 | ... L19: =L13 -> -0.76882803 | N19: =IFERROR(AVERAGE(C19:L19),0) -> -0.91799446 | O19: =IFERROR(MEDIAN(C19:L19),0) -> -0.91152101
B21: Return on Capital Employeed | C21: =IFERROR(HISTORIACLFINANCIALS!C17-HISTORIACLFINANCIALS!C23,0)/(SUM(HISTORIACLFINANCIALS!C46:C48)) -> 0.17820916 | D21: =IFERROR(HISTORIACLFINANCIALS!D17-HISTORIACLFINANCIALS!D23,0)/(SUM(HISTORIACLFINANCIALS!D46:D48)) -> 0.17611632 | E21: =IFERROR(HISTORIACLFINANCIALS!E17-HISTORIACLFINANCIALS!E23,0)/(SUM(HISTORIACLFINANCIALS!E46:E48)) -> 0.16339192 | F21: =IFERROR(HISTORIACLFINANCIALS!F17-HISTORIACLFINANCIALS!F23,0)/(SUM(HISTORIACLFINANCIALS!F46:F48)) -> 0.16316873 | G21: =IFERROR(HISTORIACLFINANCIALS!G17-HISTORIACLFINANCIALS!G23,0)/(SUM(HISTORIACLFINANCIALS!G46:G48)) -> 0.10934107 | H21: =IFERROR(HISTORIACLFINANCIALS!H17-HISTORIACLFINANCIALS!H23,0)/(SUM(HISTORIACLFINANCIALS!H46:H48)) -> 0.022028035 | I21: =IFERROR(HISTORIACLFINANCIALS!I17-HISTORIACLFINANCIALS!I23,0)/(SUM(HISTORIACLFINANCIALS!I46:I48)) -> 0.0032156244 | J21: =IFERROR(HISTORIACLFINANCIALS!J17-HISTORIACLFINANCIALS!J23,0)/(SUM(HISTORIACLFINANCIALS!J46:J48)) -> 0.068255006 | ... L21: =IFERROR(HISTORIACLFINANCIALS!L17-HISTORIACLFINANCIALS!L23,0)/(SUM(HISTORIACLFINANCIALS!L46:L48)) -> 0.36697122 | N21: =IFERROR(AVERAGE(C21:L21),0) -> 0.14035659 | O21: =IFERROR(MEDIAN(C21:L21),0) -> 0.15801875
B22: Retained Earning% | C22: =HISTORIACLFINANCIALS!C43 | D22: =HISTORIACLFINANCIALS!D43 -> 0.43353758 | E22: =HISTORIACLFINANCIALS!E43 -> 0.34479579 | F22: =HISTORIACLFINANCIALS!F43 -> 0.48995102 | G22: =HISTORIACLFINANCIALS!G43 -> 0.54675071 | H22: =HISTORIACLFINANCIALS!H43 -> -4.7463002 | I22: =HISTORIACLFINANCIALS!I43 -> 3.8383459 | J22: =HISTORIACLFINANCIALS!J43 -> -0.24075596 | ... L22: =HISTORIACLFINANCIALS!L43 -> 0.85959364 | N22: =IFERROR(AVERAGE(C22:L22),0) -> 0.23305361 | O22: =IFERROR(MEDIAN(C22:L22),0) -> 0.48995102
B23: Return on equity% | C23: =IFERROR(HISTORIACLFINANCIALS!C32,0)/SUM(HISTORIACLFINANCIALS!C46:C47) -> 0.11136987 | D23: =IFERROR(HISTORIACLFINANCIALS!D32,0)/SUM(HISTORIACLFINANCIALS!D46:D47) -> 0.10784866 | E23: =IFERROR(HISTORIACLFINANCIALS!E32,0)/SUM(HISTORIACLFINANCIALS!E46:E47) -> 0.086641259 | F23: =IFERROR(HISTORIACLFINANCIALS!F32,0)/SUM(HISTORIACLFINANCIALS!F46:F47) -> 0.10058587 | G23: =IFERROR(HISTORIACLFINANCIALS!G32,0)/SUM(HISTORIACLFINANCIALS!G46:G47) -> 0.080905834 | H23: =IFERROR(HISTORIACLFINANCIALS!H32,0)/SUM(HISTORIACLFINANCIALS!H46:H47) -> 0.0045047104 | I23: =IFERROR(HISTORIACLFINANCIALS!I32,0)/SUM(HISTORIACLFINANCIALS!I46:I47) -> -0.011537315 | J23: =IFERROR(HISTORIACLFINANCIALS!J32,0)/SUM(HISTORIACLFINANCIALS!J46:J47) -> 0.035451593 | ... L23: =IFERROR(HISTORIACLFINANCIALS!L32,0)/SUM(HISTORIACLFINANCIALS!L46:L47) -> 0.31410465 | N23: =IFERROR(AVERAGE(C23:L23),0) -> 0.093699014 | O23: =IFERROR(MEDIAN(C23:L23),0) -> 0.093613566
B24: Self Sustained Growth Rate | C24: =IFERROR(C22*C23,0) -> 0 | D24: =IFERROR(D22*D23,0) -> 0.046756448 | E24: =IFERROR(E22*E23,0) -> 0.029873541 | F24: =IFERROR(F22*F23,0) -> 0.049282151 | G24: =IFERROR(G22*G23,0) -> 0.044235323 | H24: =IFERROR(H22*H23,0) -> -0.021380708 | I24: =IFERROR(I22*I23,0) -> -0.044284204 | J24: =IFERROR(J22*J23,0) -> -0.0085351821 | ... L24: =IFERROR(L22*L23,0) -> 0.27000236 | N24: =IFERROR(AVERAGE(C24:L24),0) -> 0.042717281 | O24: =IFERROR(MEDIAN(C24:L24),0) -> 0.037054432
B25: Interest Coverage Ratio | C25: =IFERROR(HISTORIACLFINANCIALS!C17-HISTORIACLFINANCIALS!C23,0)/HISTORIACLFINANCIALS!C20 -> 67.28519 | D25: =IFERROR(HISTORIACLFINANCIALS!D17-HISTORIACLFINANCIALS!D23,0)/HISTORIACLFINANCIALS!D20 -> 73.989933 | E25: =IFERROR(HISTORIACLFINANCIALS!E17-HISTORIACLFINANCIALS!E23,0)/HISTORIACLFINANCIALS!E20 -> 20.16657 | F25: =IFERROR(HISTORIACLFINANCIALS!F17-HISTORIACLFINANCIALS!F23,0)/HISTORIACLFINANCIALS!F20 -> 101.58103 | G25: =IFERROR(HISTORIACLFINANCIALS!G17-HISTORIACLFINANCIALS!G23,0)/HISTORIACLFINANCIALS!G20 -> 40.409836 | H25: =IFERROR(HISTORIACLFINANCIALS!H17-HISTORIACLFINANCIALS!H23,0)/HISTORIACLFINANCIALS!H20 -> 11.477407 | I25: =IFERROR(HISTORIACLFINANCIALS!I17-HISTORIACLFINANCIALS!I23,0)/HISTORIACLFINANCIALS!I20 -> 1.4162717 | J25: =IFERROR(HISTORIACLFINANCIALS!J17-HISTORIACLFINANCIALS!J23,0)/HISTORIACLFINANCIALS!J20 -> 23.009091 | ... L25: =IFERROR(HISTORIACLFINANCIALS!L17-HISTORIACLFINANCIALS!L23,0)/HISTORIACLFINANCIALS!L20 -> 182.02472 | N25: =IFERROR(AVERAGE(C25:L25),0) -> 58.907285 | O25: =IFERROR(MEDIAN(C25:L25),0) -> 53.847513
B27: Debtor Turnover Ratio | C27: =IFERROR(HISTORIACLFINANCIALS!C5/HISTORIACLFINANCIALS!C58,0) -> 43.515944 | D27: =IFERROR(HISTORIACLFINANCIALS!D5/HISTORIACLFINANCIALS!D58,0) -> 56.614835 | E27: =IFERROR(HISTORIACLFINANCIALS!E5/HISTORIACLFINANCIALS!E58,0) -> 54.462536 | F27: =IFERROR(HISTORIACLFINANCIALS!F5/HISTORIACLFINANCIALS!F58,0) -> 37.213983 | G27: =IFERROR(HISTORIACLFINANCIALS!G5/HISTORIACLFINANCIALS!G58,0) -> 38.256561 | H27: =IFERROR(HISTORIACLFINANCIALS!H5/HISTORIACLFINANCIALS!H58,0) -> 54.982421 | I27: =IFERROR(HISTORIACLFINANCIALS!I5/HISTORIACLFINANCIALS!I58,0) -> 43.415974 | J27: =IFERROR(HISTORIACLFINANCIALS!J5/HISTORIACLFINANCIALS!J58,0) -> 35.612558 | ... L27: =IFERROR(HISTORIACLFINANCIALS!L5/HISTORIACLFINANCIALS!L58,0) -> 23.382265 | N27: =IFERROR(AVERAGE(C27:L27),0) -> 41.831728 | O27: =IFERROR(MEDIAN(C27:L27),0) -> 40.836268
B28: Creditor Turnover Ratio | C28: =IFERROR(HISTORIACLFINANCIALS!C5/HISTORIACLFINANCIALS!C72,0) -> 32.190609 | D28: =IFERROR(HISTORIACLFINANCIALS!D5/HISTORIACLFINANCIALS!D72,0) -> 69.545455 | E28: =IFERROR(HISTORIACLFINANCIALS!E5/HISTORIACLFINANCIALS!E72,0) -> 37.504417 | F28: =IFERROR(HISTORIACLFINANCIALS!F5/HISTORIACLFINANCIALS!F72,0) -> -100.31294 | G28: =IFERROR(HISTORIACLFINANCIALS!G5/HISTORIACLFINANCIALS!G72,0) -> -35.109049 | H28: =IFERROR(HISTORIACLFINANCIALS!H5/HISTORIACLFINANCIALS!H72,0) -> 26.258209 | I28: =IFERROR(HISTORIACLFINANCIALS!I5/HISTORIACLFINANCIALS!I72,0) -> -223.05505 | J28: =IFERROR(HISTORIACLFINANCIALS!J5/HISTORIACLFINANCIALS!J72,0) -> 58.551444 | ... L28: =IFERROR(HISTORIACLFINANCIALS!L5/HISTORIACLFINANCIALS!L72,0) -> 43.577372 | N28: =IFERROR(AVERAGE(C28:L28),0) -> -4.8134022 | O28: =IFERROR(MEDIAN(C28:L28),0) -> 34.847513
B29: Inventory Turnover Ratio | C29: =IFERROR(HISTORIACLFINANCIALS!C8/HISTORIACLFINANCIALS!C59,0) -> 13.352551 | D29: =IFERROR(HISTORIACLFINANCIALS!D8/HISTORIACLFINANCIALS!D59,0) -> 15.321261 | E29: =IFERROR(HISTORIACLFINANCIALS!E8/HISTORIACLFINANCIALS!E59,0) -> 18.664958 | F29: =IFERROR(HISTORIACLFINANCIALS!F8/HISTORIACLFINANCIALS!F59,0) -> 19.31686 | G29: =IFERROR(HISTORIACLFINANCIALS!G8/HISTORIACLFINANCIALS!G59,0) -> 17.939917 | H29: =IFERROR(HISTORIACLFINANCIALS!H8/HISTORIACLFINANCIALS!H59,0) -> 18.175008 | I29: =IFERROR(HISTORIACLFINANCIALS!I8/HISTORIACLFINANCIALS!I59,0) -> 20.264077 | J29: =IFERROR(HISTORIACLFINANCIALS!J8/HISTORIACLFINANCIALS!J59,0) -> 21.663616 | ... L29: =IFERROR(HISTORIACLFINANCIALS!L8/HISTORIACLFINANCIALS!L59,0) -> 17.005699 | N29: =IFERROR(AVERAGE(C29:L29),0) -> 18.201481 | O29: =IFERROR(MEDIAN(C29:L29),0) -> 18.419983
B30: Fixed Asset Turnover | C30: =IFERROR(HISTORIACLFINANCIALS!C5/HISTORIACLFINANCIALS!C52,0) -> 4.5962361 | D30: =IFERROR(HISTORIACLFINANCIALS!D5/HISTORIACLFINANCIALS!D52,0) -> 5.1150578 | E30: =IFERROR(HISTORIACLFINANCIALS!E5/HISTORIACLFINANCIALS!E52,0) -> 5.9609076 | F30: =IFERROR(HISTORIACLFINANCIALS!F5/HISTORIACLFINANCIALS!F52,0) -> 5.5753597 | G30: =IFERROR(HISTORIACLFINANCIALS!G5/HISTORIACLFINANCIALS!G52,0) -> 4.8055182 | H30: =IFERROR(HISTORIACLFINANCIALS!H5/HISTORIACLFINANCIALS!H52,0) -> 4.6950036 | I30: =IFERROR(HISTORIACLFINANCIALS!I5/HISTORIACLFINANCIALS!I52,0) -> 6.4252939 | J30: =IFERROR(HISTORIACLFINANCIALS!J5/HISTORIACLFINANCIALS!J52,0) -> 6.5938678 | ... L30: =IFERROR(HISTORIACLFINANCIALS!L5/HISTORIACLFINANCIALS!L52,0) -> 4.6361577 | N30: =IFERROR(AVERAGE(C30:L30),0) -> 5.3494349 | O30: =IFERROR(MEDIAN(C30:L30),0) -> 5.103002
B31: Capital Turnover Ratio | C31: =IFERROR(HISTORIACLFINANCIALS!C5/SUM(HISTORIACLFINANCIALS!C46:C48),0) -> 1.8669299 | D31: =IFERROR(HISTORIACLFINANCIALS!D5/SUM(HISTORIACLFINANCIALS!D46:D48),0) -> 1.8127624 | E31: =IFERROR(HISTORIACLFINANCIALS!E5/SUM(HISTORIACLFINANCIALS!E46:E48),0) -> 1.8699397 | F31: =IFERROR(HISTORIACLFINANCIALS!F5/SUM(HISTORIACLFINANCIALS!F46:F48),0) -> 1.82149 | G31: =IFERROR(HISTORIACLFINANCIALS!G5/SUM(HISTORIACLFINANCIALS!G46:G48),0) -> 1.5254924 | H31: =IFERROR(HISTORIACLFINANCIALS!H5/SUM(HISTORIACLFINANCIALS!H46:H48),0) -> 1.3267347 | I31: =IFERROR(HISTORIACLFINANCIALS!I5/SUM(HISTORIACLFINANCIALS!I46:I48),0) -> 1.5841353 | J31: =IFERROR(HISTORIACLFINANCIALS!J5/SUM(HISTORIACLFINANCIALS!J46:J48),0) -> 1.8650684 | ... L31: =IFERROR(HISTORIACLFINANCIALS!L5/SUM(HISTORIACLFINANCIALS!L46:L48),0) -> 1.5874382 | N31: =IFERROR(AVERAGE(C31:L31),0) -> 1.6914225 | O31: =IFERROR(MEDIAN(C31:L31),0) -> 1.7334984
B33: Debtor Days | C33: =IFERROR(365/C27,0) -> 8.3877303 | D33: =IFERROR(365/D27,0) -> 6.4470735 | E33: =IFERROR(365/E27,0) -> 6.7018547 | F33: =IFERROR(365/F27,0) -> 9.8081412 | G33: =IFERROR(365/G27,0) -> 9.5408472 | H33: =IFERROR(365/H27,0) -> 6.6384855 | I33: =IFERROR(365/I27,0) -> 8.4070438 | J33: =IFERROR(365/J27,0) -> 10.249193 | ... L33: =IFERROR(365/L27,0) -> 15.610121 | N33: =IFERROR(AVERAGE(C33:L33),0) -> 9.361802 | O33: =IFERROR(MEDIAN(C33:L33),0) -> 8.9739455
B34: Payable Days | C34: =IFERROR(365/C28,0) -> 11.338711 | D34: =IFERROR(365/D28,0) -> 5.248366 | E34: =IFERROR(365/E28,0) -> 9.7321869 | F34: =IFERROR(365/F28,0) -> -3.6386134 | G34: =IFERROR(365/G28,0) -> -10.39618 | H34: =IFERROR(365/H28,0) -> 13.900415 | I34: =IFERROR(365/I28,0) -> -1.6363673 | J34: =IFERROR(365/J28,0) -> 6.2338343 | ... L34: =IFERROR(365/L28,0) -> 8.3759066 | N34: =IFERROR(AVERAGE(C34:L34),0) -> 4.7703164 | O34: =IFERROR(MEDIAN(C34:L34),0) -> 7.3048704
B35: Inventory Days | C35: =IFERROR(365/C29,0) -> 27.335601 | D35: =IFERROR(365/D29,0) -> 23.823104 | E35: =IFERROR(365/E29,0) -> 19.555362 | F35: =IFERROR(365/F29,0) -> 18.89541 | G35: =IFERROR(365/G29,0) -> 20.34569 | H35: =IFERROR(365/H29,0) -> 20.082522 | I35: =IFERROR(365/I29,0) -> 18.01217 | J35: =IFERROR(365/J29,0) -> 16.848526 | ... L35: =IFERROR(365/L29,0) -> 21.463393 | N35: =IFERROR(AVERAGE(C35:L35),0) -> 20.433246 | O35: =IFERROR(MEDIAN(C35:L35),0) -> 19.818942
B36: Cash Conversion Cycle | C36: =IFERROR(SUM(C33,C35)-C34,0) -> 24.384621 | D36: =IFERROR(SUM(D33,D35)-D34,0) -> 25.021812 | E36: =IFERROR(SUM(E33,E35)-E34,0) -> 16.525029 | F36: =IFERROR(SUM(F33,F35)-F34,0) -> 32.342165 | G36: =IFERROR(SUM(G33,G35)-G34,0) -> 40.282718 | H36: =IFERROR(SUM(H33,H35)-H34,0) -> 12.820592 | I36: =IFERROR(SUM(I33,I35)-I34,0) -> 28.055581 | J36: =IFERROR(SUM(J33,J35)-J34,0) -> 20.863885 | ... L36: =IFERROR(SUM(L33,L35)-L34,0) -> 28.697608 | N36: =IFERROR(AVERAGE(C36:L36),0) -> 25.024731 | O36: =IFERROR(MEDIAN(C36:L36),0) -> 24.703216
B38: CFO/Sales | C38: =IFERROR(HISTORIACLFINANCIALS!C77/HISTORIACLFINANCIALS!C5,0) -> 0.17263714 | D38: =IFERROR(HISTORIACLFINANCIALS!D77/HISTORIACLFINANCIALS!D5,0) -> 0.18322685 | E38: =IFERROR(HISTORIACLFINANCIALS!E77/HISTORIACLFINANCIALS!E5,0) -> 0.18289826 | F38: =IFERROR(HISTORIACLFINANCIALS!F77/HISTORIACLFINANCIALS!F5,0) -> 0.061416198 | G38: =IFERROR(HISTORIACLFINANCIALS!G77/HISTORIACLFINANCIALS!G5,0) -> 0.012225747 | H38: =IFERROR(HISTORIACLFINANCIALS!H77/HISTORIACLFINANCIALS!H5,0) -> 0.18746092 | I38: =IFERROR(HISTORIACLFINANCIALS!I77/HISTORIACLFINANCIALS!I5,0) -> -0.011004214 | J38: =IFERROR(HISTORIACLFINANCIALS!J77/HISTORIACLFINANCIALS!J5,0) -> 0.081873723 | ... L38: =IFERROR(HISTORIACLFINANCIALS!L77/HISTORIACLFINANCIALS!L5,0) -> 0.1030586 | N38: =IFERROR(AVERAGE(C38:L38),0) -> 0.11043602 | O38: =IFERROR(MEDIAN(C38:L38),0) -> 0.1168128
B39: CFO/Total Asset | C39: =IFERROR(HISTORIACLFINANCIALS!C77/HISTORIACLFINANCIALS!C63,0) -> 0.23269476 | D39: =IFERROR(HISTORIACLFINANCIALS!D77/HISTORIACLFINANCIALS!D63,0) -> 0.24008622 | E39: =IFERROR(HISTORIACLFINANCIALS!E77/HISTORIACLFINANCIALS!E63,0) -> 0.24228029 | F39: =IFERROR(HISTORIACLFINANCIALS!F77/HISTORIACLFINANCIALS!F63,0) -> 0.082634163 | G39: =IFERROR(HISTORIACLFINANCIALS!G77/HISTORIACLFINANCIALS!G63,0) -> 0.014537693 | H39: =IFERROR(HISTORIACLFINANCIALS!H77/HISTORIACLFINANCIALS!H63,0) -> 0.18482377 | I39: =IFERROR(HISTORIACLFINANCIALS!I77/HISTORIACLFINANCIALS!I63,0) -> -0.013019804 | J39: =IFERROR(HISTORIACLFINANCIALS!J77/HISTORIACLFINANCIALS!J63,0) -> 0.11378668 | ... L39: =IFERROR(HISTORIACLFINANCIALS!L77/HISTORIACLFINANCIALS!L63,0) -> 0.11941242 | N39: =IFERROR(AVERAGE(C39:L39),0) -> 0.13778723 | O39: =IFERROR(MEDIAN(C39:L39),0) -> 0.14002425
B40: CFO/Total Debt | C40: =IFERROR(HISTORIACLFINANCIALS!C77/HISTORIACLFINANCIALS!C48,0) -> 43.057601 | D40: =IFERROR(HISTORIACLFINANCIALS!D77/HISTORIACLFINANCIALS!D48,0) -> 25.796112 | E40: =IFERROR(HISTORIACLFINANCIALS!E77/HISTORIACLFINANCIALS!E48,0) -> 120.83609 | F40: =IFERROR(HISTORIACLFINANCIALS!F77/HISTORIACLFINANCIALS!F48,0) -> 33.120301 | G40: =IFERROR(HISTORIACLFINANCIALS!G77/HISTORIACLFINANCIALS!G48,0) -> 5.0244432 | H40: =IFERROR(HISTORIACLFINANCIALS!H77/HISTORIACLFINANCIALS!H48,0) -> 24.388981 | I40: =IFERROR(HISTORIACLFINANCIALS!I77/HISTORIACLFINANCIALS!I48,0) -> -2.2843713 | J40: =IFERROR(HISTORIACLFINANCIALS!J77/HISTORIACLFINANCIALS!J48,0) -> 7.7174697 | ... L40: =IFERROR(HISTORIACLFINANCIALS!L77/HISTORIACLFINANCIALS!L48,0) -> 181.13793 | N40: =IFERROR(AVERAGE(C40:L40),0) -> 59.496657 | O40: =IFERROR(MEDIAN(C40:L40),0) -> 29.458207

Sheet FORECASTING
B3: ='Data Sheet'!B1&" - "&HISTORIACLFINANCIALS!B5 -> MARUTI SUZUKI INDIA LTD - SALES
B4: YEAR WEIGHT | C4: YEAR | D4: SALES | E4: SALES GROWTH | G4: YEAR WEIGHT | H4: YEAR | I4: SALES | J4: SALES GROWTH
B5: 1 | C5: =HISTORIACLFINANCIALS!$C$3 -> 42460 | D5: {=TRANSPOSE(HISTORIACLFINANCIALS!C5:L5)} -> 57589 | E5: - | G5: 1 | H5: =HISTORIACLFINANCIALS!$C$3 -> 42460
B6: =B5+1 -> 2 | C6: =C5+365 -> 42825 | D6: 68085 | E6: =D6/D5-1 -> 0.18225703 | G6: =G5+1 -> 2 | H6: =H5+365 -> 42825
B7: =B6+1 -> 3 | C7: =C6+365 -> 43190 | D7: 79809.4 | E7: =D7/D6-1 -> 0.17220239 | G7: =G6+1 -> 3 | H7: =H6+365 -> 43190
B8: =B7+1 -> 4 | C8: =C7+365 -> 43555 | D8: 86068.5 | E8: =D8/D7-1 -> 0.078425599 | G8: =G7+1 -> 4 | H8: =H7+365 -> 43555
B9: =B8+1 -> 5 | C9: =C8+365 -> 43920 | D9: 75660 | E9: =D9/D8-1 -> -0.12093275 | G9: =G8+1 -> 5 | H9: =H8+365 -> 43920
B10: =B9+1 -> 6 | C10: =C9+365 -> 44285 | D10: 70372 | E10: =D10/D9-1 -> -0.06989162 | G10: =G9+1 -> 6 | H10: =H9+365 -> 44285
B11: =B10+1 -> 7 | C11: =C10+365 -> 44650 | D11: 88329.8 | E11: =D11/D10-1 -> 0.25518388 | G11: =G10+1 -> 7 | H11: =H10+365 -> 44650
B12: =B11+1 -> 8 | C12: =C11+365 -> 45015 | D12: 117571.3 | E12: =D12/D11-1 -> 0.33104909 | G12: =G11+1 -> 8 | H12: =H11+365 -> 45015
B13: =B12+1 -> 9 | C13: =C12+365 -> 45380 | D13: 141858.2 | E13: =D13/D12-1 -> 0.20657167 | G13: =G12+1 -> 9 | H13: =H12+365 -> 45380
B14: =B13+1 -> 10 | C14: =C13+365 -> 45745 | D14: 152913 | E14: =D14/D13-1 -> 0.077928523 | G14: =G13+1 -> 10 | H14: =H13+365 -> 45745
B15: =B14+1 -> 11 | C15: =C14+365 -> 46110 | D15: =FORECAST(B15,_xlfn.ANCHORARRAY($D$5),$B$5:$B$14) -> 145980.08 | E15: =D15/D14-1 -> -0.045338984 | G15: =G14+1 -> 11 | H15: =H14+365 -> 46110
B16: =B15+1 -> 12 | C16: =C15+365 -> 46475 | D16: =FORECAST(B16,_xlfn.ANCHORARRAY($D$5),$B$5:$B$14) -> 155462.71 | E16: =D16/D15-1 -> 0.064958377 | G16: =G15+1 -> 12 | H16: =H15+365 -> 46475
B17: =B16+1 -> 13 | C17: =C16+365 -> 46840 | D17: =FORECAST(B17,_xlfn.ANCHORARRAY($D$5),$B$5:$B$14) -> 164945.34 | E17: =D17/D16-1 -> 0.060996165 | G17: =G16+1 -> 13 | H17: =H16+365 -> 46840
B18: =B17+1 -> 14 | C18: =C17+365 -> 47205 | D18: =FORECAST(B18,_xlfn.ANCHORARRAY($D$5),$B$5:$B$14) -> 174427.97 | E18: =D18/D17-1 -> 0.057489525 | G18: =G17+1 -> 14 | H18: =H17+365 -> 47205
B19: =B18+1 -> 15 | C19: =C18+365 -> 47570 | D19: =FORECAST(B19,_xlfn.ANCHORARRAY($D$5),$B$5:$B$14) -> 183910.6 | E19: =D19/D18-1 -> 0.054364155 | G19: =G18+1 -> 15 | H19: =H18+365 -> 47570
B21: SUMMARY OUTPUT
B24: Multiple R | C24: 0.88345136
B25: R Square | C25: 0.78048631
B26: Adjusted R Square | C26: 0.7530471
B27: Standard Error | C27: 16149.493
B28: Observations | C28: 10
B30: ANOVA
C31: df | D31: SS | E31: MS | F31: F | G31: Significance F
B32: Regression | C32: 1 | D32: 7.418421e+09 | E32: 7.418421e+09 | F32: 28.444196 | G32: 0.00069973879
B33: Residual | C33: 8 | D33: 2.0864491e+09 | E33: 2.6080614e+08
B34: Total | C34: 9 | D34: 9.5048701e+09
C36: Coefficients | D36: Standard Error | E36: t Stat | F36: P-value | G36: Lower 95% | H36: Upper 95% | I36: Lower 95.0% | J36: Upper 95.0%
B37: Intercept | C37: 41671.16 | D37: 11032.204 | E37: 3.7772288 | F37: 0.0054095058 | G37: 16230.851 | H37: 67111.469 | I37: 16230.851 | J37: 67111.469
B38: X Variable 1 | C38: 9482.6291 | D38: 1778.0007 | E38: 5.3333101 | F38: 0.00069973879 | G38: 5382.5521 | H38: 13582.706 | I38: 5382.5521 | J38: 13582.706

Sheet Data Sheet
A1: COMPANY NAME | B1: MARUTI SUZUKI INDIA LTD | E1: =IF(B2<>B3, "A NEW VERSION OF THE WORKSHEET IS AVAILABLE", "")
A2: LATEST VERSION | B2: 2.1 | E2: PLEASE DO NOT MAKE ANY CHANGES TO THIS SHEET
A3: CURRENT VERSION | B3: 2.1
A5: META
A6: Number of shares | B6: =IF(B9>0, B9/B8, 0) -> 31.440256
A7: Face Value | B7: 5
A8: Current Price | B8: 14294.95
A9: Market Capitalization | B9: 449436.89
A15: PROFIT & LOSS
A16: Report Date | B16: 42460 | C16: 42825 | D16: 43190 | E16: 43555 | F16: 43921 | G16: 44286 | H16: 44651 | I16: 45016 | J16: 45382 | K16: 45747
A17: Sales | B17: 57589 | C17: 68085 | D17: 79809.4 | E17: 86068.5 | F17: 75660 | G17: 70372 | H17: 88329.8 | I17: 117571.3 | J17: 141858.2 | K17: 152913
A18: Raw Material Cost | B18: 38701.2 | C18: 47121.5 | D18: 54945.3 | E18: 59346.6 | F18: 53402 | G18: 50550.5 | H18: 66137.1 | I18: 86654.7 | J18: 100119.5 | K18: 108718.3
A19: Change in Inventory | B19: -4.8 | C19: 379.3 | D19: -40.8 | E19: -211.6 | F19: 238.7 | G19: -273.6 | H19: 93.1 | I19: 403.9 | J19: 378.6 | K19: 1227.5
A20: Power and Fuel | B20: 694.1 | C20: 518.6 | D20: 673.4 | E20: 863.3 | F20: 699.5 | G20: 476.6 | H20: 630.9 | I20: 790 | J20: 1033.4 | K20: 1052.6
A21: Other Mfr. Exp | B21: 427.8 | C21: 382.9 | D21: 462.1 | E21: 475.7 | F21: 378.1 | G21: 683.3 | H21: 852.5 | I21: 1120.7 | J21: 939.3 | K21: 1994.4
A22: Employee Cost | B22: 2000.3 | C22: 2360.3 | D22: 2863.4 | E22: 3285 | F22: 3416.2 | G22: 3431.6 | H22: 4051.4 | I22: 4634.6 | J22: 6301.6 | K22: 7026
A23: Selling and admin | B23: 5367.3 | C23: 6111.3 | D23: 6755.3 | E23: 8390.3 | F23: 8456.3 | G23: 7924 | H23: 9119.1 | I23: 11695 | J23: 12082.6 | K23: 11523.3
A24: Other Expenses | B24: 1369.4 | C24: 1548.4 | D24: 1951.2 | E24: 2439.7 | F24: 2191.6 | G24: 1621.8 | H24: 1879.9 | I24: 2051 | J24: 3134.1 | K24: 3602.3
A25: Other Income | B25: 1464.1 | C25: 2399.2 | D25: 2154.6 | E25: 2664.2 | F25: 3410.4 | G25: 3046.3 | H25: 1860.8 | I25: 2306.6 | J25: 4247.6 | K25: 5198.8
A26: Depreciation | B26: 2821.8 | C26: 2603.9 | D26: 2759.8 | E26: 3020.8 | F26: 3528.4 | G26: 3034.1 | H26: 2789 | I26: 2825.7 | J26: 5255.8 | K26: 5608.2
A27: Interest | B27: 81.7 | C27: 89.4 | D27: 345.8 | E27: 75.9 | F27: 134.2 | G27: 101.8 | H27: 126.6 | I27: 187 | J27: 193.6 | K27: 194.2
... A31: Dividend Amount | B31: 1057 | C31: 2265 | D31: 2416 | E31: 2416 | F31: 1812 | G31: 1359 | H31: 1812 | I31: 2718 | J31: 3930 | K31: 4244.4
A40: Quarters
A41: Report Date | B41: 45199 | C41: 45291 | D41: 45382 | E41: 45473 | F41: 45565 | G41: 45657 | H41: 45747 | I41: 45838 | J41: 45930 | K41: 46022
A42: Sales | B42: 37339.4 | C42: 33512.8 | D42: 38471.2 | E42: 35779.4 | F42: 37449.2 | G42: 38764.3 | H42: 40920.1 | I42: 38605.2 | J42: 42344.2 | K42: 49904.1
A43: Expenses | B43: 32027.9 | C43: 29072.8 | D43: 33250.1 | E43: 30672.8 | F43: 32450.4 | G43: 33687.8 | H43: 36076.1 | I43: 33982.6 | J43: 37258.2 | K43: 44331
A44: Other Income | B44: 957.8 | C44: 1052.9 | D44: 1261 | E44: 1118.1 | F44: 1570.5 | G44: 1124.8 | H44: 1583.1 | I44: 1923.7 | J44: 1013.5 | K44: 1140.5
A45: Depreciation | B45: 1341.9 | C45: 1301.5 | D45: 1298.3 | E45: 1331.7 | F45: 1385.7 | G45: 1429 | H45: 1461.8 | I45: 1556 | J45: 1703 | K45: 1734.6
A46: Interest | B46: 35.1 | C46: 35.8 | D46: 76.2 | E46: 57.3 | F46: 43 | G46: 46.3 | H46: 47.6 | I46: 46.8 | J46: 57.2 | K46: 61.7
A47: Profit before tax | B47: 4892.3 | C47: 4155.6 | D47: 5107.6 | E47: 4835.7 | F47: 5140.6 | G47: 4726 | H47: 4917.7 | I47: 4943.5 | J47: 4339.3 | K47: 4917.3
A48: Tax | B48: 1106.1 | C48: 948.8 | E48: 1076 | F48: 2038.1 | G48: 999.1 | H48: 1006.6 | I48: 1151.1 | J48: 990.3 | K48: 1038.2
A49: Net profit | B49: 3786.2 | C49: 3206.8 | D49: 3952.3 | E49: 3759.7 | F49: 3102.5 | G49: 3726.9 | H49: 3911.1 | I49: 3792.4 | J49: 3349 | K49: 3879.1
A50: Operating Profit | B50: 5311.5 | C50: 4440 | D50: 5221.1 | E50: 5106.6 | F50: 4998.8 | G50: 5076.5 | H50: 4844 | I50: 4622.6 | J50: 5086 | K50: 5573.1
A55: BALANCE SHEET
A56: Report Date | B56: 42460 | C56: 42825 | D56: 43190 | E56: 43555 | F56: 43921 | G56: 44286 | H56: 44651 | I56: 45016 | J56: 45382 | K56: 45747
A57: Equity Share Capital | B57: 151 | C57: 151 | D57: 151 | E57: 151 | F57: 151 | G57: 151 | H57: 151 | I57: 151 | J57: 157.2 | K57: 157.2
A58: Reserves | B58: 30465 | C58: 36924.1 | D58: 42408.4 | E58: 46941.1 | F58: 49262 | G58: 52349.6 | H58: 55182.5 | I58: 61640.3 | J58: 85478.8 | K58: 96082.7
A59: Borrowings | B59: 230.9 | C59: 483.6 | D59: 120.8 | E59: 159.6 | F59: 184.1 | G59: 540.9 | H59: 425.5 | I59: 1247.3 | J59: 118.6 | K59: 87
A60: Other Liabilities | B60: 11878.6 | C60: 14401.8 | D60: 17568.2 | E60: 16717 | F60: 14030.6 | G60: 18334.6 | H60: 18896.5 | I60: 21558.3 | J60: 29549.5 | K60: 35644.3
A61: Total | B61: 42725.5 | C61: 51960.5 | D61: 60248.4 | E61: 63968.7 | F61: 63627.7 | G61: 71376.1 | H61: 74655.5 | I61: 84596.9 | J61: 115304.1 | K61: 131971.2
...

Sheet Cash Flow
C2: 41699 | D2: 42064 | E2: 42430 | F2: 42795 | G2: 43160 | H2: 43525 | I2: 43891 | J2: 44256 | K2: 44621 | L2: 44986 | M2: 45352 | N2: 45717
B3: Cash from Operating Activity - | C3: 4995 | D3: 6449 | E3: 8482 | F3: 10282 | G3: 11788 | H3: 6601 | I3: 3496 | J3: 8856 | K3: 1840 | L3: 9251 | M3: 16801 | N3: 16136
B4: Profit from operations | C4: 5111 | D4: 6779 | E4: 8935 | F4: 10413 | G4: 12036 | H4: 11060 | I4: 7503 | J4: 5531 | K4: 5832 | L4: 11112 | M4: 18676 | N4: 20322
B5: Receivables | C5: 46 | D5: 345 | E5: -204 | F5: 122 | G5: -262 | H5: -851 | I5: 340 | J5: 696 | K5: -764 | L5: -1258 | M5: -1316 | N5: -1969
B6: Inventory | C6: 124 | D6: -982 | E6: -450 | F6: -131 | G6: 104 | H6: -162 | I6: 109 | J6: 165 | K6: -483 | L6: -751 | M6: 125 | N6: -1595
B7: Payables | C7: 813 | D7: 712 | E7: 1789 | F7: 979 | G7: 2128 | H7: -858 | I7: -2155 | J7: 2680 | K7: -396 | L7: 2008 | M7: 3321 | N7: 3509
B8: Loans Advances | C8: -563 | D8: 23 | E8: -1 | F8: 1 | G8: 0 | H8: -13 | I8: -1 | J8: -6 | K8: -8 | L8: 1 | M8: -3 | N8: -10
B9: Other WC items | C9: 321 | D9: 648 | E9: 325 | F9: 1222 | G9: 839 | H9: 569 | I9: -863 | J9: 801 | K9: -1162 | L9: 374 | M9: -406 | N9: -313
B10: Working capital changes | C10: 742 | D10: 745 | E10: 1460 | F10: 2192 | G10: 2808 | H10: -1315 | I10: -2570 | J10: 4336 | K10: -2813 | L10: 373 | M10: 1722 | N10: -378
B11: Direct taxes | C11: -858 | D11: -1075 | E11: -1912 | F11: -2323 | G11: -3056 | H11: -3144 | I11: -1438 | J11: -1011 | K11: -1178 | L11: -2233 | M11: -3597 | N11: -3807
B12: Cash from Investing Activity - | C12: -4997 | D12: -4491 | E12: -7230 | F12: -9173 | G12: -8302 | H12: -3540 | I12: -557 | J12: -7291 | K12: -239 | L12: -8036 | M12: -11865 | N12: -14456
B13: Fixed assets purchased | C13: -3545 | D13: -3058 | E13: -2469 | F13: -3391 | G13: -3912 | H13: -4872 | I13: -3437 | J13: -2370 | K13: -3459 | L13: -6347 | M13: -9200 | N13: -10641
B14: Fixed assets sold | C14: 9 | D14: 16 | E14: 12 | F14: 16 | G14: 26 | H14: 170 | I14: 37 | J14: 42 | K14: 136 | L14: 100 | M14: 45 | N14: 38
... B29: Net Cash Flow | C29: -76 | D29: -45 | E29: 16 | F29: -20 | G29: 50 | H29: 113 | I29: -165 | J29: 20 | K29: -6 | L29: 2 | M29: 874 | N29: -2475
